2024-06-22 19:10:25,787 INFO    StreamThr :3463 [internal.py:wandb_internal():85] W&B internal server running at pid: 3463, started at: 2024-06-22 19:10:25.786654
2024-06-22 19:10:25,788 DEBUG   HandlerThread:3463 [handler.py:handle_request():158] handle_request: status
2024-06-22 19:10:25,788 INFO    WriterThread:3463 [datastore.py:open_for_write():87] open: /Users/zhemingan/anaconda3/lib/python3.11/site-packages/signaturesnet/wandb/run-20240622_191025-uwodml6e/run-uwodml6e.wandb
2024-06-22 19:10:25,790 DEBUG   SenderThread:3463 [sender.py:send():378] send: header
2024-06-22 19:10:25,790 DEBUG   SenderThread:3463 [sender.py:send():378] send: run
2024-06-22 19:10:25,937 ERROR   SenderThread:3463 [internal_api.py:execute():344] 404 response executing GraphQL.
2024-06-22 19:10:25,937 ERROR   SenderThread:3463 [internal_api.py:execute():345] {"errors":[{"message":"project not found","path":["upsertBucket"]}],"data":{"upsertBucket":null}}
2024-06-22 19:10:25,937 ERROR   SenderThread:3463 [sender.py:send_run():970] [Errno 32] Broken pipe
Traceback (most recent call last):
  File "/Users/zhemingan/anaconda3/lib/python3.11/site-packages/wandb/sdk/internal/internal_api.py", line 340, in execute
    return self.client.execute(*args, **kwargs)  # type: ignore
           ^^^^^^^^^^^^^^^^^^^^^^^^^^^^^^^^^^^^
  File "/Users/zhemingan/anaconda3/lib/python3.11/site-packages/wandb/vendor/gql-0.2.0/wandb_gql/client.py", line 52, in execute
    result = self._get_result(document, *args, **kwargs)
             ^^^^^^^^^^^^^^^^^^^^^^^^^^^^^^^^^^^^^^^^^^^
  File "/Users/zhemingan/anaconda3/lib/python3.11/site-packages/wandb/vendor/gql-0.2.0/wandb_gql/client.py", line 60, in _get_result
    return self.transport.execute(document, *args, **kwargs)
           ^^^^^^^^^^^^^^^^^^^^^^^^^^^^^^^^^^^^^^^^^^^^^^^^^
  File "/Users/zhemingan/anaconda3/lib/python3.11/site-packages/wandb/sdk/lib/gql_request.py", line 59, in execute
    request.raise_for_status()
  File "/Users/zhemingan/anaconda3/lib/python3.11/site-packages/requests/models.py", line 1021, in raise_for_status
    raise HTTPError(http_error_msg, response=self)
requests.exceptions.HTTPError: 404 Client Error: Not Found for url: https://api.wandb.ai/graphql

During handling of the above exception, another exception occurred:

Traceback (most recent call last):
  File "/Users/zhemingan/anaconda3/lib/python3.11/site-packages/wandb/apis/normalize.py", line 41, in wrapper
    return func(*args, **kwargs)
           ^^^^^^^^^^^^^^^^^^^^^
  File "/Users/zhemingan/anaconda3/lib/python3.11/site-packages/wandb/sdk/internal/internal_api.py", line 2188, in upsert_run
    response = self.gql(
               ^^^^^^^^^
  File "/Users/zhemingan/anaconda3/lib/python3.11/site-packages/wandb/sdk/internal/internal_api.py", line 312, in gql
    ret = self._retry_gql(
          ^^^^^^^^^^^^^^^^
  File "/Users/zhemingan/anaconda3/lib/python3.11/site-packages/wandb/sdk/lib/retry.py", line 131, in __call__
    result = self._call_fn(*args, **kwargs)
             ^^^^^^^^^^^^^^^^^^^^^^^^^^^^^^
  File "/Users/zhemingan/anaconda3/lib/python3.11/site-packages/wandb/sdk/internal/internal_api.py", line 347, in execute
    wandb.termerror(f"Error while calling W&B API: {error} ({response})")
  File "/Users/zhemingan/anaconda3/lib/python3.11/site-packages/wandb/errors/term.py", line 64, in termerror
    _log(
  File "/Users/zhemingan/anaconda3/lib/python3.11/site-packages/wandb/errors/term.py", line 103, in _log
    click.echo(line, file=sys.stderr, nl=newline)
  File "/Users/zhemingan/anaconda3/lib/python3.11/site-packages/click/utils.py", line 298, in echo
    file.write(out)  # type: ignore
    ^^^^^^^^^^^^^^^
BrokenPipeError: [Errno 32] Broken pipe

During handling of the above exception, another exception occurred:

Traceback (most recent call last):
  File "/Users/zhemingan/anaconda3/lib/python3.11/site-packages/wandb/sdk/internal/sender.py", line 968, in send_run
    server_run = self._init_run(run, config_value_dict)
                 ^^^^^^^^^^^^^^^^^^^^^^^^^^^^^^^^^^^^^^
  File "/Users/zhemingan/anaconda3/lib/python3.11/site-packages/wandb/sdk/internal/sender.py", line 1013, in _init_run
    server_run, inserted, server_messages = self._api.upsert_run(
                                            ^^^^^^^^^^^^^^^^^^^^^
  File "/Users/zhemingan/anaconda3/lib/python3.11/site-packages/wandb/apis/normalize.py", line 87, in wrapper
    raise CommError(message, err).with_traceback(sys.exc_info()[2])
  File "/Users/zhemingan/anaconda3/lib/python3.11/site-packages/wandb/apis/normalize.py", line 41, in wrapper
    return func(*args, **kwargs)
           ^^^^^^^^^^^^^^^^^^^^^
  File "/Users/zhemingan/anaconda3/lib/python3.11/site-packages/wandb/sdk/internal/internal_api.py", line 2188, in upsert_run
    response = self.gql(
               ^^^^^^^^^
  File "/Users/zhemingan/anaconda3/lib/python3.11/site-packages/wandb/sdk/internal/internal_api.py", line 312, in gql
    ret = self._retry_gql(
          ^^^^^^^^^^^^^^^^
  File "/Users/zhemingan/anaconda3/lib/python3.11/site-packages/wandb/sdk/lib/retry.py", line 131, in __call__
    result = self._call_fn(*args, **kwargs)
             ^^^^^^^^^^^^^^^^^^^^^^^^^^^^^^
  File "/Users/zhemingan/anaconda3/lib/python3.11/site-packages/wandb/sdk/internal/internal_api.py", line 347, in execute
    wandb.termerror(f"Error while calling W&B API: {error} ({response})")
  File "/Users/zhemingan/anaconda3/lib/python3.11/site-packages/wandb/errors/term.py", line 64, in termerror
    _log(
  File "/Users/zhemingan/anaconda3/lib/python3.11/site-packages/wandb/errors/term.py", line 103, in _log
    click.echo(line, file=sys.stderr, nl=newline)
  File "/Users/zhemingan/anaconda3/lib/python3.11/site-packages/click/utils.py", line 298, in echo
    file.write(out)  # type: ignore
    ^^^^^^^^^^^^^^^
wandb.errors.CommError: [Errno 32] Broken pipe
2024-06-22 19:10:29,870 DEBUG   HandlerThread:3463 [handler.py:handle_request():158] handle_request: status_report
2024-06-22 19:10:30,961 DEBUG   HandlerThread:3463 [handler.py:handle_request():158] handle_request: status_report
2024-06-22 19:10:34,887 DEBUG   HandlerThread:3463 [handler.py:handle_request():158] handle_request: status_report
