2024-06-06 10:04:52,319 INFO    MainThread:19445 [wandb_setup.py:_flush():76] Current SDK version is 0.17.0
2024-06-06 10:04:52,319 INFO    MainThread:19445 [wandb_setup.py:_flush():76] Configure stats pid to 19445
2024-06-06 10:04:52,319 INFO    MainThread:19445 [wandb_setup.py:_flush():76] Loading settings from /Users/zhemingan/.config/wandb/settings
2024-06-06 10:04:52,319 INFO    MainThread:19445 [wandb_setup.py:_flush():76] Loading settings from /Users/zhemingan/anaconda3/lib/python3.11/site-packages/signaturesnet/wandb/settings
2024-06-06 10:04:52,319 INFO    MainThread:19445 [wandb_setup.py:_flush():76] Loading settings from environment variables: {}
2024-06-06 10:04:52,319 INFO    MainThread:19445 [wandb_setup.py:_flush():76] Applying setup settings: {'_disable_service': False}
2024-06-06 10:04:52,319 INFO    MainThread:19445 [wandb_setup.py:_flush():76] Inferring run settings from compute environment: {'program_relpath': 'train_classifier.py', 'program_abspath': '/Users/zhemingan/anaconda3/lib/python3.11/site-packages/signaturesnet/train_classifier.py', 'program': '/Users/zhemingan/anaconda3/lib/python3.11/site-packages/signaturesnet/train_classifier.py'}
2024-06-06 10:04:52,319 INFO    MainThread:19445 [wandb_setup.py:_flush():76] Applying login settings: {}
2024-06-06 10:04:52,319 INFO    MainThread:19445 [wandb_init.py:_log_setup():520] Logging user logs to /Users/zhemingan/anaconda3/lib/python3.11/site-packages/signaturesnet/wandb/run-20240606_100452-6akjpaf4/logs/debug.log
2024-06-06 10:04:52,320 INFO    MainThread:19445 [wandb_init.py:_log_setup():521] Logging internal logs to /Users/zhemingan/anaconda3/lib/python3.11/site-packages/signaturesnet/wandb/run-20240606_100452-6akjpaf4/logs/debug-internal.log
2024-06-06 10:04:52,320 INFO    MainThread:19445 [wandb_init.py:init():560] calling init triggers
2024-06-06 10:04:52,320 INFO    MainThread:19445 [wandb_init.py:init():567] wandb.init called with sweep_config: {}
config: {'data_id': 'datasets/detector', 'model_id': 'classifier_final', 'models_dir': '../trained_models/test_exp/', 'iterations': 20, 'num_classes': 72, 'sigmoid_params': [5000, 1000], 'batch_size': 100, 'lr': 0.00043, 'enable_logging': True, 'wandb_project_id': 'classifier', 'num_hidden_layers': 3, 'num_neurons': 260, 'device': 'cuda'}
2024-06-06 10:04:52,320 INFO    MainThread:19445 [wandb_init.py:init():610] starting backend
2024-06-06 10:04:52,320 INFO    MainThread:19445 [wandb_init.py:init():614] setting up manager
2024-06-06 10:04:52,323 INFO    MainThread:19445 [backend.py:_multiprocessing_setup():105] multiprocessing start_methods=spawn,fork,forkserver, using: spawn
2024-06-06 10:04:52,325 INFO    MainThread:19445 [wandb_init.py:init():622] backend started and connected
2024-06-06 10:04:52,336 INFO    MainThread:19445 [wandb_init.py:init():711] updated telemetry
2024-06-06 10:04:52,337 INFO    MainThread:19445 [wandb_init.py:init():744] communicating run to backend with 90.0 second timeout
2024-06-06 10:04:52,489 ERROR   MainThread:19445 [wandb_init.py:init():770] encountered error: It appears that you do not have permission to access the requested resource. Please reach out to the project owner to grant you access. If you have the correct permissions, verify that there are no issues with your networking setup.(Error 404: Not Found)
2024-06-06 10:04:52,489 ERROR   MainThread:19445 [wandb_init.py:init():1174] error in wandb.init()
Traceback (most recent call last):
  File "/Users/zhemingan/anaconda3/lib/python3.11/site-packages/wandb/sdk/wandb_init.py", line 1164, in init
    return wi.init()
           ^^^^^^^^^
  File "/Users/zhemingan/anaconda3/lib/python3.11/site-packages/wandb/sdk/wandb_init.py", line 776, in init
    raise error
wandb.errors.CommError: It appears that you do not have permission to access the requested resource. Please reach out to the project owner to grant you access. If you have the correct permissions, verify that there are no issues with your networking setup.(Error 404: Not Found)
2024-06-06 16:32:20,181 WARNING MsgRouterThr:19445 [router.py:message_loop():77] message_loop has been closed
