2024-05-30 10:47:24,970 INFO    MainThread:94187 [wandb_setup.py:_flush():76] Current SDK version is 0.17.0
2024-05-30 10:47:24,970 INFO    MainThread:94187 [wandb_setup.py:_flush():76] Configure stats pid to 94187
2024-05-30 10:47:24,970 INFO    MainThread:94187 [wandb_setup.py:_flush():76] Loading settings from /Users/zhemingan/.config/wandb/settings
2024-05-30 10:47:24,970 INFO    MainThread:94187 [wandb_setup.py:_flush():76] Loading settings from /Users/zhemingan/anaconda3/lib/python3.11/site-packages/signaturesnet/wandb/settings
2024-05-30 10:47:24,970 INFO    MainThread:94187 [wandb_setup.py:_flush():76] Loading settings from environment variables: {}
2024-05-30 10:47:24,970 INFO    MainThread:94187 [wandb_setup.py:_flush():76] Applying setup settings: {'_disable_service': False}
2024-05-30 10:47:24,970 INFO    MainThread:94187 [wandb_setup.py:_flush():76] Inferring run settings from compute environment: {'program_relpath': 'train_classifier.py', 'program_abspath': '/Users/zhemingan/anaconda3/lib/python3.11/site-packages/signaturesnet/train_classifier.py', 'program': '/Users/zhemingan/anaconda3/lib/python3.11/site-packages/signaturesnet/train_classifier.py'}
2024-05-30 10:47:24,970 INFO    MainThread:94187 [wandb_setup.py:_flush():76] Applying login settings: {}
2024-05-30 10:47:24,970 INFO    MainThread:94187 [wandb_setup.py:_flush():76] Applying login settings: {}
2024-05-30 10:47:24,970 INFO    MainThread:94187 [wandb_setup.py:_flush():76] Applying login settings: {'api_key': '***REDACTED***'}
2024-05-30 10:47:24,970 INFO    MainThread:94187 [wandb_setup.py:_flush():76] Applying login settings: {'api_key': '***REDACTED***'}
2024-05-30 10:47:24,970 INFO    MainThread:94187 [wandb_setup.py:_flush():76] Applying login settings: {}
2024-05-30 10:47:24,970 ERROR   MainThread:94187 [wandb_setup.py:_flush():78] error in wandb.init()
Traceback (most recent call last):
  File "/Users/zhemingan/anaconda3/lib/python3.11/site-packages/spyder_kernels/customize/spydercustomize.py", line 473, in exec_code
    exec_fun(compile(ast_code, filename, 'exec'), ns_globals, ns_locals)
  File "/Users/zhemingan/anaconda3/lib/python3.11/site-packages/spyder_kernels/py3compat.py", line 356, in compat_exec
    exec(code, globals, locals)
  File "/Users/zhemingan/anaconda3/lib/python3.11/site-packages/signaturesnet/train_classifier.py", line 59, in <module>
    score = train_classifier(config=config)
            ^^^^^^^^^^^^^^^^^^^^^^^^^^^^^^^
  File "/Users/zhemingan/anaconda3/lib/python3.11/site-packages/signaturesnet/trainers/classifier_trainer.py", line 119, in train_classifier
    run = wandb.init(project=config["wandb_project_id"],
          ^^^^^^^^^^^^^^^^^^^^^^^^^^^^^^^^^^^^^^^^^^^^^^
  File "/Users/zhemingan/anaconda3/lib/python3.11/site-packages/wandb/sdk/wandb_init.py", line 1178, in init
    wandb._sentry.reraise(e)
  File "/Users/zhemingan/anaconda3/lib/python3.11/site-packages/wandb/analytics/sentry.py", line 155, in reraise
    raise exc.with_traceback(sys.exc_info()[2])
  File "/Users/zhemingan/anaconda3/lib/python3.11/site-packages/wandb/sdk/wandb_init.py", line 1163, in init
    wi.setup(kwargs)
  File "/Users/zhemingan/anaconda3/lib/python3.11/site-packages/wandb/sdk/wandb_init.py", line 300, in setup
    wandb_login._login(
  File "/Users/zhemingan/anaconda3/lib/python3.11/site-packages/wandb/sdk/wandb_login.py", line 334, in _login
    wlogin.prompt_api_key()
  File "/Users/zhemingan/anaconda3/lib/python3.11/site-packages/wandb/sdk/wandb_login.py", line 263, in prompt_api_key
    raise UsageError("api_key not configured (no-tty). call " + directive)
wandb.errors.UsageError: api_key not configured (no-tty). call wandb.login(key=[your_api_key])
2024-05-30 10:47:24,970 ERROR   MainThread:94187 [wandb_setup.py:_flush():78] error in wandb.init()
Traceback (most recent call last):
  File "/Users/zhemingan/anaconda3/lib/python3.11/site-packages/spyder_kernels/customize/spydercustomize.py", line 473, in exec_code
    exec_fun(compile(ast_code, filename, 'exec'), ns_globals, ns_locals)
  File "/Users/zhemingan/anaconda3/lib/python3.11/site-packages/spyder_kernels/py3compat.py", line 356, in compat_exec
    exec(code, globals, locals)
  File "/Users/zhemingan/anaconda3/lib/python3.11/site-packages/signaturesnet/train_classifier.py", line 59, in <module>
    score = train_classifier(config=config)
            ^^^^^^^^^^^^^^^^^^^^^^^^^^^^^^^
  File "/Users/zhemingan/anaconda3/lib/python3.11/site-packages/signaturesnet/trainers/classifier_trainer.py", line 119, in train_classifier
    run = wandb.init(project=config["wandb_project_id"],
          ^^^^^^^^^^^^^^^^^^^^^^^^^^^^^^^^^^^^^^^^^^^^^^
  File "/Users/zhemingan/anaconda3/lib/python3.11/site-packages/wandb/sdk/wandb_init.py", line 1178, in init
    wandb._sentry.reraise(e)
  File "/Users/zhemingan/anaconda3/lib/python3.11/site-packages/wandb/analytics/sentry.py", line 155, in reraise
    raise exc.with_traceback(sys.exc_info()[2])
  File "/Users/zhemingan/anaconda3/lib/python3.11/site-packages/wandb/sdk/wandb_init.py", line 1163, in init
    wi.setup(kwargs)
  File "/Users/zhemingan/anaconda3/lib/python3.11/site-packages/wandb/sdk/wandb_init.py", line 300, in setup
    wandb_login._login(
  File "/Users/zhemingan/anaconda3/lib/python3.11/site-packages/wandb/sdk/wandb_login.py", line 334, in _login
    wlogin.prompt_api_key()
  File "/Users/zhemingan/anaconda3/lib/python3.11/site-packages/wandb/sdk/wandb_login.py", line 263, in prompt_api_key
    raise UsageError("api_key not configured (no-tty). call " + directive)
wandb.errors.UsageError: api_key not configured (no-tty). call wandb.login(key=[your_api_key])
2024-05-30 10:47:24,971 INFO    MainThread:94187 [wandb_init.py:_log_setup():520] Logging user logs to /Users/zhemingan/anaconda3/lib/python3.11/site-packages/signaturesnet/wandb/run-20240530_104724-r4hfvym5/logs/debug.log
2024-05-30 10:47:24,971 INFO    MainThread:94187 [wandb_init.py:_log_setup():521] Logging internal logs to /Users/zhemingan/anaconda3/lib/python3.11/site-packages/signaturesnet/wandb/run-20240530_104724-r4hfvym5/logs/debug-internal.log
2024-05-30 10:47:24,971 INFO    MainThread:94187 [wandb_init.py:init():560] calling init triggers
2024-05-30 10:47:24,971 INFO    MainThread:94187 [wandb_init.py:init():567] wandb.init called with sweep_config: {}
config: {'data_id': 'datasets/detector', 'model_id': 'classifier_final', 'models_dir': '../trained_models/test_exp/', 'iterations': 20, 'num_classes': 72, 'sigmoid_params': [5000, 1000], 'batch_size': 100, 'lr': 0.00043, 'enable_logging': True, 'wandb_project_id': 'classifier', 'num_hidden_layers': 3, 'num_neurons': 260, 'device': 'cuda'}
2024-05-30 10:47:24,971 INFO    MainThread:94187 [wandb_init.py:init():610] starting backend
2024-05-30 10:47:24,971 INFO    MainThread:94187 [wandb_init.py:init():614] setting up manager
2024-05-30 10:47:24,972 INFO    MainThread:94187 [backend.py:_multiprocessing_setup():105] multiprocessing start_methods=spawn,fork,forkserver, using: spawn
2024-05-30 10:47:24,974 INFO    MainThread:94187 [wandb_init.py:init():622] backend started and connected
2024-05-30 10:47:24,978 INFO    MainThread:94187 [wandb_init.py:init():711] updated telemetry
2024-05-30 10:47:24,978 INFO    MainThread:94187 [wandb_init.py:init():744] communicating run to backend with 90.0 second timeout
2024-05-30 10:47:25,141 ERROR   MainThread:94187 [wandb_init.py:init():770] encountered error: [Errno 32] Broken pipe
2024-05-30 10:47:25,141 ERROR   MainThread:94187 [wandb_init.py:init():1174] error in wandb.init()
Traceback (most recent call last):
  File "/Users/zhemingan/anaconda3/lib/python3.11/site-packages/wandb/sdk/wandb_init.py", line 1164, in init
    return wi.init()
           ^^^^^^^^^
  File "/Users/zhemingan/anaconda3/lib/python3.11/site-packages/wandb/sdk/wandb_init.py", line 776, in init
    raise error
wandb.errors.CommError: [Errno 32] Broken pipe
2024-05-30 10:48:01,640 INFO    MainThread:94187 [wandb_settings.py:_apply_login():1895] Applying login settings: {'api_key': '***REDACTED***'}
2024-05-30 10:48:01,644 INFO    MainThread:94187 [wandb_settings.py:_apply_login():1895] Applying login settings: {'api_key': '***REDACTED***'}
2024-05-30 10:48:06,542 WARNING MsgRouterThr:94187 [router.py:message_loop():77] message_loop has been closed
